<?xml version="1.0"?>
<robot xmlns:xacro="http://www.ros.org/wiki/xacro">

    <xacro:include filename="inertial_macros.xacro"/>

    <material name="white">
        <color rgba="1 1 1 1"/>
    </material>

    <material name="orange">
        <color rgba="1 0.3 0.1 1"/>
    </material>

    <material name="blue">
        <color rgba="0.2 0.2 1 1"/>
    </material>

    <material name="black">
        <color rgba="0 0 0 1"/>
    </material>

    <!-- BASE LINK-->
    <!-- base link origin centre point between two wheels -->
    <link name="base_link">

    </link>

    <!-- CHASSIS LINK -->
    <joint name="chassis joint" type="fixed">
        <parent link="base_link"/>
        <child link="chassis" />
        <origin xyz ="-0.045 0 0"/>
    </joint>

    <link name="chassis">
        <visual>
            <origin xyz="0.11 0 0.045"/> <!-- by default, chassis origin is in the centre, so shift it  forward by half in x and up by half in z-->
            <geometry>
                <box size="0.22 0.14 0.09"/>
            </geometry>
            <material name="white"/>
        </visual>
        <collision>
            <origin xyz="0.11 0 0.045"/> <!-- by default, chassis origin is in the centre, so shift it  forward by half in x and up by half in z-->
            <geometry>
                <box size="0.22 0.14 0.09"/>
            </geometry>
        </collision>
        <xacro:inertial_box mass="0.75" x="0.22" y="0.14" z="0.09">
            <origin xyz="0.11 0 0.045" rpy="0 0 0 "/>
        </xacro:inertial_box>
    </link>

    <gazebo reference="chassis">
        <material>Gazebo/White</material>
    </gazebo>


    <!-- LEFT WHEEL LINK -->
    <joint name = "left_wheel_joint" type="continuous">
        <parent link="base_link"/>
        <child link = "left_wheel"/>
        <origin xyz="0 0.1 -0.035" rpy="-${pi/2} 0 0"/> <!-- The left wheel is 0.1m left and 0.035m below the base link origin, and rotated to be on its side-->
        <axis xyz="0 0 1"/> <!-- Forward rotation is positive around z axis-->
    </joint>

    <link name = "left_wheel">
        <visual>
            <geometry>
                <cylinder radius="0.034" length="0.025"/>
            </geometry>
            <material name="blue"/>
        </visual>
        <collision>
            <geometry>
                <cylinder radius="0.034" length="0.025"/>
            </geometry>
        </collision>
        <xacro:inertial_cylinder mass="0.1" length="0.025" radius="0.034">
            <origin xyz="0 0 0" rpy="0 0 0"/>
        </xacro:inertial_cylinder>
    </link>

    <gazebo reference="left_wheel">
        <material>Gazebo/Blue</material>
    </gazebo>


    <!-- RIGHT WHEEL LINK -->
    <joint name = "right_wheel_joint" type="continuous">
        <parent link="base_link"/>
        <child link = "right_wheel"/>
        <origin xyz="0 -0.095 -0.035" rpy="${pi/2} 0 0"/> <!-- The left wheel is 0.1m left and 0.035m below the base link origin, and rotated to be on its side-->
        <axis xyz="0 0 -1"/> <!-- Forward rotation is positive around -z axis-->
    </joint>

    <link name = "right_wheel">
        <visual>
            <geometry>
                <cylinder radius="0.034" length="0.025"/>
            </geometry>
            <material name="blue"/>
        </visual>
        <collision>
            <geometry>
                <cylinder radius="0.034" length="0.025"/>
            </geometry>
        </collision>
        <xacro:inertial_cylinder mass="0.1" length="0.025" radius="0.034">
            <origin xyz="0 0 0" rpy="0 0 0"/>
        </xacro:inertial_cylinder>
    </link>

    <gazebo reference="right_wheel">
        <material>Gazebo/Blue</material>
    </gazebo>

    <!-- CASTER WHEEL LINK -->

    <joint name="caster_wheel_joint" type="fixed">
        <parent link="chassis"/>
        <child link="caster_wheel"/>
        <origin xyz="0.125 0 0"/>
    </joint>


    <link name="caster_wheel">
        <visual>
            <geometry>
                <sphere radius="0.07"/>
            </geometry>
            <material name="black"/>
        </visual>
        <collision>
            <geometry>
                <sphere radius="0.07"/>
            </geometry>
        </collision>
        <xacro:inertial_sphere mass="0.1" radius="0.07">
            <origin xyz="0 0 0" rpy="0 0 0"/>
        </xacro:inertial_sphere>
    </link>

    <gazebo reference="caster_wheel">
        <material>Gazebo/Black</material>
        <mu1 value="0.001"/>
        <mu2 value="0.001"/>
    </gazebo>

</robot>